2023-02-24 21:08:31 | Traceback (most recent call last):
  File "D:\Python\HW_OOP_Exeption\app.py", line 32, in <module>
    main()
  File "D:\Python\HW_OOP_Exeption\app.py", line 11, in main
    person = Employee('John', 300, 'John@gmail.com')
             ^^^^^^^^^^^^^^^^^^^^^^^^^^^^^^^^^^^^^^^
  File "D:\Python\HW_OOP_Exeption\employee.py", line 20, in __init__
    self.validate()
  File "D:\Python\HW_OOP_Exeption\employee.py", line 33, in validate
    raise EmailAlreadyExistsException(f"Email '{self.email}' already exists.")
employee.EmailAlreadyExistsException: Email 'John@gmail.com' already exists.

